Workbook
Name in_Mode: 'Inputs'!$B$6
Name in_Case: 'Inputs'!$B$7
Name in_MultLow: 'Inputs'!$B$8
Name in_MultBase: 'Inputs'!$B$9
Name in_MultHigh: 'Inputs'!$B$10
Name in_StartCash: 'Inputs'!$B$11
Name in_ModelStart: 'Inputs'!$B$12
Name in_PricePouch: 'Inputs'!$B$16
Name in_SubDisc: 'Inputs'!$B$17
Name in_PriceStick: 'Inputs'!$B$18
Name in_PriceStickBox: 'Inputs'!$B$19
Name in_WsPouch: 'Inputs'!$B$20
Name in_WsStick: 'Inputs'!$B$21
Name in_DistDisc: 'Inputs'!$B$22
Name in_FoundDisc: 'Inputs'!$B$23
Name in_ShakerCost: 'Inputs'!$B$24
Name in_CogsStd: 'Inputs'!$B$28
Name in_CogsLean: 'Inputs'!$B$29
Name in_StickCogsStd: 'Inputs'!$B$30
Name in_StickCogsLean: 'Inputs'!$B$31
Name in_ShipOrder: 'Inputs'!$B$32
Name in_FreeShip: 'Inputs'!$B$33
Name in_ShipCharge: 'Inputs'!$B$34
Name in_CardPct: 'Inputs'!$B$35
Name in_CardFixed: 'Inputs'!$B$36
Name in_FreightPouch: 'Inputs'!$B$37
Name in_FreightStick: 'Inputs'!$B$38
Name in_FreightDist: 'Inputs'!$B$39
Name in_SubShare: 'Inputs'!$B$43
Name in_SubChurn: 'Inputs'!$B$44
Name in_Repeat: 'Inputs'!$B$45
Name in_PouchPerOrder: 'Inputs'!$B$46
Name in_StickAttach: 'Inputs'!$B$47
Name in_SticksPerBox: 'Inputs'!$B$48
Name in_CAC: 'Inputs'!$B$49
Name in_WaitSize: 'Inputs'!$B$50
Name in_WaitConv: 'Inputs'!$B$51
Name in_StoreChurn: 'Inputs'!$B$52
Name in_PouchPerStore: 'Inputs'!$B$53
Name in_StickPerStore: 'Inputs'!$B$54
Name in_Net30: 'Inputs'!$B$55
Name in_SampleBudget: 'Inputs'!$B$56
Name in_SampleStart: 'Inputs'!$B$57
Name in_RunLean: 'Inputs'!$B$61
Name in_RunStd: 'Inputs'!$B$62
Name in_StickRunLean: 'Inputs'!$B$63
Name in_StickRunStd: 'Inputs'!$B$64
Name in_Cover: 'Inputs'!$B$65
Name in_Lead: 'Inputs'!$B$66
Name in_PODate: 'Inputs'!$B$67
Name in_Deposit: 'Inputs'!$B$68
Name in_BalanceDate: 'Inputs'!$B$69
Name in_FirstShip: 'Inputs'!$B$70
Name in_SampleCreditLean: 'Inputs'!$B$71
Name in_SampleCreditStd: 'Inputs'!$B$72
Name in_Flavor2On: 'Inputs'!$B$73
Name in_Flavor2Run: 'Inputs'!$B$74
Name in_HydraOn: 'Inputs'!$B$75
Name in_FxShopify: 'Inputs'!$B$79
Name in_FxShopify_Start: 'Inputs'!$D$79

Sheet README
A1: Picked financial model: how to use it
A2: Version 1.0, built Oct 2026 from STRATEGY.md, TIMELINE.md, EXPANSION.md, OPERATIONS.md and LAUNCH_GUIDE.md. Pre-launch: nothing in this file is an actual sale.
A4: How to use it
A5: 1. Go to Inputs. Yellow cells are the only cells to change. Every input has a source / note saying where the figure came from.
A6: 2. Pick the run-size mode (Lean = 144-unit runs at Pure Private Label, Standard = 1,000-unit runs) and the demand case (Low / Base / High).
A7: 3. Set starting cash to the money you will actually put in, and replace the demand table (section 8) with your own plan.
A8: 4. Read Monthly Cash Flow for the month-by-month view: the summary at the top gives the cash low point, break-even month and cash at Jun / Dec 2027.
A9: 5. Read Scenarios to see all three demand cases, and Lean vs Standard, side by side. Read Unit Economics for contribution per order, CAC payback and LTV.
A10: 6. Save a copy with a new version number before big changes (picked-model-v1.1.xlsx) so there is a trail.
A12: What is an estimate (replace with quotes, in this order)
A13: 1. Pouch cost of goods: $23 standard is STRATEGY.md's estimate; $30 lean is a placeholder (small runs cost more). Only the whey price is sourced. Replace both with manufacturer quotes first: they drive every margin.
A14: 2. Stick pack cost ($1.30), the lean stick run size (1,440 assumes 144 boxes of 10) and stick freight ($0.10).
... A37: No invented sales: every volume is a labelled scenario assumption. No credentials. Brand colours: #F0505E headers, #1E1A17 text, #FFF7EC fills; yellow = input.

Sheet Inputs
A1: Picked: model inputs
A2: Yellow cells are inputs. Change them; every other sheet recalculates. Nothing here is an actual sale: demand rows are scenario assumptions the owner sets.
A4: 1. Model settings
A5: Input | B5: Value | E5: Unit | F5: Source / note
A6: Run-size mode (Lean = 144-unit runs, Standard = 1,000-unit runs) | B6: Lean | E6: list | F6: TOGGLE. Lean follows EXPANSION.md / TIMELINE.md lean path (Pure Private Label 144-unit MOQ). Standard follows LAUNCH_GUIDE.md 1,000-pouch budget.
A7: Demand case shown on Monthly Cash Flow | B7: Base | E7: list | F7: TOGGLE: Low / Base / High. Scales every demand row below by the multiplier for that case.
A8: Demand multiplier: Low case | B8: 0.5 | E8: x | F8: SCENARIO ASSUMPTION. Owner sets.
A9: Demand multiplier: Base case | B9: 1 | E9: x | F9: SCENARIO ASSUMPTION. 1.0 = the demand table exactly as entered.
A10: Demand multiplier: High case | B10: 1.5 | E10: x | F10: SCENARIO ASSUMPTION. Owner sets.
A11: Starting cash on 1 Oct 2026 | B11: 25000 | E11: $ | F11: OWNER INPUT. TIMELINE.md: lean path about $15k-25k through May 2027; standard path about $65k-95k. Set to the cash you will actually put in.
A12: First month of the model | B12: 46296 | E12: date | F12: Structural. Model runs 15 months from here (Oct 2026 to Dec 2027). Use the first day of a month.
A14: 2. Prices
A15: Input | B15: Value | E15: Unit | F15: Source / note
A16: Pouch, 20 servings, one-off price | B16: 54.99 | E16: $/pouch | F16: STRATEGY.md range and price table.
A17: Subscription discount | B17: 0.15 | E17: % | F17: STRATEGY.md: pouch on subscription 15% off ($46.74).
A18: Single stick, suggested retail at a counter | B18: 3.99 | E18: $/stick | F18: STRATEGY.md. This is the store's shelf price; Picked receives the wholesale stick price. Used for the retailer-margin check.
A19: Stick pack box of 10, own website | B19: 34.99 | E19: $/box | F19: STRATEGY.md.
A20: Wholesale price per pouch (direct to store) | B20: 27.5 | E20: $/pouch | F20: STRATEGY.md proposed store terms. A proposal until the owner confirms.
A21: Wholesale price per stick | B21: 2 | E21: $/stick | F21: STRATEGY.md proposed store terms (keystone against $3.99 SRP). A proposal until the owner confirms.
A22: Distributor discount off wholesale | B22: 0.25 | E22: % | F22: STRATEGY.md / LAUNCH_GUIDE.md: about 25% distributor margin. Unit Economics only; distributors are not in the monthly plan.
A23: Founding offer: discount on waitlist first order | B23: 0.2 | E23: % | F23: STRATEGY.md founding offer: 20% off the first pouch plus a free shaker. Applied on top of normal pricing (conservative).
A24: Founding offer: cost of one free shaker | B24: 4 | E24: $/shaker | F24: ESTIMATE, no quote. Replace with the shaker supplier's quote.
A26: 3. Unit costs and fees
A27: Input | B27: Value | E27: Unit | F27: Source / note
A28: Pouch landed cost of goods, Standard run (1,000) | B28: 23 | E28: $/pouch | F28: STRATEGY.md estimate $21-25, plan on $23. Only the whey price is sourced (USDA, about $14/lb). QUOTE PENDING: replace with manufacturer quote.
A29: Pouch landed cost of goods, Lean run (144) | B29: 30 | E29: $/pouch | F29: ESTIMATE, small runs cost more, replace with quote (Pure Private Label 144-unit run). EXPANSION.md: 144 pouches for about $3.5k-5k.
A30: Protein stick pack cost of goods, Standard run | B30: 1.3 | E30: $/stick | F30: LAUNCH_GUIDE.md budget: stick packs at about $1.30. ESTIMATE, quote pending.
A31: Protein stick pack cost of goods, Lean run | B31: 1.3 | E31: $/stick | F31: ESTIMATE: no small-run quote; set equal to standard until quoted. Small runs likely cost more.
A32: Shipping and packing per DTC order | B32: 8 | E32: $/order | F32: STRATEGY.md 'about $8'. OPERATIONS.md: postage $8-13 at the 2 lb rate (less if cubic applies) plus a $0.18-0.28 mailer.
A33: Free shipping on DTC orders? (1 = yes, Picked absorbs; 0 = customer pays) | B33: 1 | E33: 1/0 | F33: ASSUMPTION matching STRATEGY.md's margin table, which deducts the full $8. OPERATIONS.md plans free shipping over $50.
A34: Shipping charged to customer when free shipping is off | B34: 8 | E34: $/order | F34: ASSUMPTION. Only used when the free-shipping input is 0.
A35: Card fee, percent | B35: 0.029 | E35: % | F35: OPERATIONS.md: Shopify Payments on Basic, 2.9% + 30c.
A36: Card fee, fixed per order | B36: 0.3 | E36: $/order | F36: OPERATIONS.md.
A37: Freight to a store, per pouch | B37: 1 | E37: $/pouch | F37: STRATEGY.md: about $1 freight.
A38: Freight to a store, per stick | B38: 0.1 | E38: $/stick | F38: ESTIMATE, no source. Replace with real shipping cost per counter box.
A39: Freight to a distributor, per pouch | B39: 0 | E39: $/pouch | F39: STRATEGY.md distributor row shows none.
A41: 4. Customers, retention and acquisition (scenario assumptions)
A42: Input | B42: Value | E42: Unit | F42: Source / note
A43: Share of new DTC customers who subscribe | B43: 0.25 | E43: % | F43: SCENARIO ASSUMPTION, conservative. Replace with the Shopify subscription share once orders exist.
A44: Monthly churn of subscribers | B44: 0.12 | E44: %/month | F44: SCENARIO ASSUMPTION. Subscribers receive one pouch a month.
...

Sheet Unit Economics
A1: Picked: unit economics per order
A2: Estimates from the Inputs sheet. Contribution is before marketing and fixed costs.
A4: A. At Standard-run cost of goods (reconciles to STRATEGY.md's table)
A5: Channel | B5: Price received | C5: Goods | D5: Shipping / freight | E5: Card fees | F5: Contribution | G5: Margin | H5: STRATEGY.md says (at $23 goods)
A6: DTC one-off pouch | B6: =in_PricePouch | C6: =in_CogsStd | D6: =in_ShipOrder | E6: =B6*in_CardPct+in_CardFixed | F6: =B6-C6-D6-E6 | G6: =IF(B6=0,0,F6/B6) | H6: about $22
A7: DTC subscription pouch | B7: =in_PricePouch*(1-in_SubDisc) | C7: =in_CogsStd | D7: =in_ShipOrder | E7: =B7*in_CardPct+in_CardFixed | F7: =B7-C7-D7-E7 | G7: =IF(B7=0,0,F7/B7) | H7: about $14
A8: Wholesale direct to store, pouch | B8: =in_WsPouch | C8: =in_CogsStd | D8: =in_FreightPouch | E8: =0 | F8: =B8-C8-D8-E8 | G8: =IF(B8=0,0,F8/B8) | H8: about $3.50
A9: Distributor, pouch (25% off wholesale) | B9: =in_WsPouch*(1-in_DistDisc) | C9: =in_CogsStd | D9: =in_FreightDist | E9: =0 | F9: =B9-C9-D9-E9 | G9: =IF(B9=0,0,F9/B9) | H9: a loss
A10: DTC stick box of 10 | B10: =in_PriceStickBox | C10: =in_StickCogsStd*in_SticksPerBox | D10: =in_ShipOrder | E10: =B10*in_CardPct+in_CardFixed | F10: =B10-C10-D10-E10 | G10: =IF(B10=0,0,F10/B10) | H10: n/a
A11: Wholesale stick (single) | B11: =in_WsStick | C11: =in_StickCogsStd | D11: =in_FreightStick | E11: =0 | F11: =B11-C11-D11-E11 | G11: =IF(B11=0,0,F11/B11) | H11: n/a
A13: B. At the active run-size mode's cost of goods (Inputs toggle)
A14: Channel | B14: Price received | C14: Goods | D14: Shipping / freight | E14: Card fees | F14: Contribution | G14: Margin | H14: STRATEGY.md says (at $23 goods)
A15: DTC one-off pouch | B15: =in_PricePouch | C15: =IF(in_Mode="Lean",in_CogsLean,in_CogsStd) | D15: =in_ShipOrder | E15: =B15*in_CardPct+in_CardFixed | F15: =B15-C15-D15-E15 | G15: =IF(B15=0,0,F15/B15) | H15: about $22
A16: DTC subscription pouch | B16: =in_PricePouch*(1-in_SubDisc) | C16: =IF(in_Mode="Lean",in_CogsLean,in_CogsStd) | D16: =in_ShipOrder | E16: =B16*in_CardPct+in_CardFixed | F16: =B16-C16-D16-E16 | G16: =IF(B16=0,0,F16/B16) | H16: about $14
A17: Wholesale direct to store, pouch | B17: =in_WsPouch | C17: =IF(in_Mode="Lean",in_CogsLean,in_CogsStd) | D17: =in_FreightPouch | E17: =0 | F17: =B17-C17-D17-E17 | G17: =IF(B17=0,0,F17/B17) | H17: about $3.50
A18: Distributor, pouch (25% off wholesale) | B18: =in_WsPouch*(1-in_DistDisc) | C18: =IF(in_Mode="Lean",in_CogsLean,in_CogsStd) | D18: =in_FreightDist | E18: =0 | F18: =B18-C18-D18-E18 | G18: =IF(B18=0,0,F18/B18) | H18: a loss
A19: DTC stick box of 10 | B19: =in_PriceStickBox | C19: =IF(in_Mode="Lean",in_StickCogsLean,in_StickCogsStd)*in_SticksPerBox | D19: =in_ShipOrder | E19: =B19*in_CardPct+in_CardFixed | F19: =B19-C19-D19-E19 | G19: =IF(B19=0,0,F19/B19) | H19: n/a
A20: Wholesale stick (single) | B20: =in_WsStick | C20: =IF(in_Mode="Lean",in_StickCogsLean,in_StickCogsStd) | D20: =in_FreightStick | E20: =0 | F20: =B20-C20-D20-E20 | G20: =IF(B20=0,0,F20/B20) | H20: n/a
A21: Active mode: | B21: =in_Mode
A22: Retailer margin on a single stick at SRP | B22: =(in_PriceStick-in_WsStick)/in_PriceStick | H22: STRATEGY.md: keystone, 50% retailer margin
A23: Pouch goods cost at which distributors break even | B23: =in_WsPouch*(1-in_DistDisc)-in_FreightDist | H23: STRATEGY.md: go to distributors only once goods cost $16 or less
A25: C. CAC payback and lifetime value (contribution, undiscounted, before fixed costs)
A26: Measure | B26: Standard COGS | C26: Active mode | H26: How it is calculated
A27: CAC (paid cost per first order) | B27: =in_CAC | C27: =in_CAC | H27: Inputs
A28: Contribution, DTC one-off order | B28: =F6 | C28: =F15 | H28: Table A / B
A29: Contribution, DTC subscription order | B29: =F7 | C29: =F16 | H29: Table A / B
A30: First one-off order contribution after CAC | B30: =B28-B27 | C30: =C28-C27 | H30: Negative = the first order does not pay for the ad
A31: One-off orders needed to pay back CAC | B31: =IF(B28<=0,"never",B27/B28) | C31: =IF(C28<=0,"never",C27/C28) | H31: CAC / one-off contribution
A32: Subscription months to pay back CAC | B32: =IF(B29<=0,"never",B27/B29) | C32: =IF(C29<=0,"never",C27/C29) | H32: CAC / subscription contribution
A33: Expected orders per one-off customer | B33: =1/(1-in_Repeat) | C33: =1/(1-in_Repeat) | H33: 1 / (1 - repeat rate)
A34: Expected orders (months) per subscriber | B34: =1/in_SubChurn | C34: =1/in_SubChurn | H34: 1 / monthly churn
A35: LTV, one-off customer | B35: =B28*B33 | C35: =C28*C33 | H35: Contribution x expected orders
A36: LTV, subscriber | B36: =B29*B34 | C36: =C29*C34 | H36: Contribution x expected months
A37: Blended LTV per new DTC customer | B37: =in_SubShare*B36+(1-in_SubShare)*B35 | C37: =in_SubShare*C36+(1-in_SubShare)*C35 | H37: Weighted by subscription share
A38: LTV : CAC | B38: =IF(B27=0,"n/a",B37/B27) | C38: =IF(C27=0,"n/a",C37/C27) | H38: Common rule of thumb: aim for 3x or better
A39: Highest CAC that still breaks even over the lifetime | B39: =B37 | C39: =C37 | H39: Equals blended LTV
A40: CAC that keeps a 3:1 LTV : CAC | B40: =B37/3 | C40: =C37/3 | H40: Blended LTV / 3

Sheet Monthly Cash Flow
A1: Picked: monthly cash flow (mode and demand case from Inputs)
A2: Months Oct 2026 to Dec 2027. All figures are projections from the Inputs sheet, not actual results. Cash view: inventory is a cash outflow when bought; COGS appears only in the operating view at the bottom.
A3: Run-size mode | B3: =in_Mode
A4: Demand multiplier | B4: =IF(in_Case="Low",in_MultLow,IF(in_Case="High",in_MultHigh,in_MultBase))
A5: Demand case | B5: =in_Case
A6: Pouch cost of goods (by mode) | B6: =IF($B$3="Lean",in_CogsLean,in_CogsStd)
A7: Stick cost of goods (by mode) | B7: =IF($B$3="Lean",in_StickCogsLean,in_StickCogsStd)
A8: Pouch run size (by mode) | B8: =IF($B$3="Lean",in_RunLean,in_RunStd)
A9: Stick run size (by mode) | B9: =IF($B$3="Lean",in_StickRunLean,in_StickRunStd)
A10: Sample credit on first order (by mode) | B10: =IF($B$3="Lean",in_SampleCreditLean,in_SampleCreditStd)
A12: Summary for this sheet's mode and case
A13: Lowest cash balance | B13: =MIN($C$120:$Q$120)
A14: Month of lowest cash balance | B14: =INDEX($C$23:$Q$23,MATCH(MIN($C$120:$Q$120),$C$120:$Q$120,0))
A15: Peak funding need (lowest cumulative net cash flow) | B15: =MIN(0,MIN($C$119:$Q$119))
A16: Operating break-even month (first month operating profit >= 0) | B16: =IFERROR(INDEX($C$23:$Q$23,MATCH(1,$C$127:$Q$127,0)),"Not by Dec 2027")
A17: Cash payback month (cumulative net cash flow back to >= 0) | B17: =IFERROR(INDEX($C$23:$Q$23,MATCH(1,$C$128:$Q$128,0)),"Not by Dec 2027")
A18: Cash balance, end of Jun 2027 | B18: =IFERROR(INDEX($C$120:$Q$120,MATCH(DATE(2027,6,1),$C$23:$Q$23,0)),"n/a")
A19: Cash balance, end of Dec 2027 | B19: =IFERROR(INDEX($C$120:$Q$120,MATCH(DATE(2027,12,1),$C$23:$Q$23,0)),"n/a")
A20: Stockout check (pouch + stick units short; should be 0) | B20: =SUM($C$54:$Q$54)+SUM($C$65:$Q$65)
A21: Operating profit, Oct 2026 to Dec 2027 (launch costs excluded) | B21: =SUM($C$126:$Q$126)
A23: Line | B23: Note | C23: =DATE(YEAR(in_ModelStart),MONTH(in_ModelStart),1) | D23: =EDATE(C23,1) | E23: =EDATE(D23,1) | F23: =EDATE(E23,1) | G23: =EDATE(F23,1) | H23: =EDATE(G23,1) | I23: =EDATE(H23,1) | J23: =EDATE(I23,1) | K23: =EDATE(J23,1) | ... Q23: =EDATE(P23,1) | R23: Total
A24: Selling? (1 from the first ship month) | C24: =IF(C$23>=DATE(YEAR(in_FirstShip),MONTH(in_FirstShip),1),1,0) | D24: =IF(D$23>=DATE(YEAR(in_FirstShip),MONTH(in_FirstShip),1),1,0) | E24: =IF(E$23>=DATE(YEAR(in_FirstShip),MONTH(in_FirstShip),1),1,0) | F24: =IF(F$23>=DATE(YEAR(in_FirstShip),MONTH(in_FirstShip),1),1,0) | G24: =IF(G$23>=DATE(YEAR(in_FirstShip),MONTH(in_FirstShip),1),1,0) | H24: =IF(H$23>=DATE(YEAR(in_FirstShip),MONTH(in_FirstShip),1),1,0) | I24: =IF(I$23>=DATE(YEAR(in_FirstShip),MONTH(in_FirstShip),1),1,0) | J24: =IF(J$23>=DATE(YEAR(in_FirstShip),MONTH(in_FirstShip),1),1,0) | ... Q24: =IF(Q$23>=DATE(YEAR(in_FirstShip),MONTH(in_FirstShip),1),1,0)
A26: DTC customers and orders
A27: Waitlist first orders (first ship month only) | B27: Waitlist x conversion | C27: =IF(EOMONTH(in_FirstShip,0)=EOMONTH(C$23,0),in_WaitSize*in_WaitConv*$B$4,0) | D27: =IF(EOMONTH(in_FirstShip,0)=EOMONTH(D$23,0),in_WaitSize*in_WaitConv*$B$4,0) | E27: =IF(EOMONTH(in_FirstShip,0)=EOMONTH(E$23,0),in_WaitSize*in_WaitConv*$B$4,0) | F27: =IF(EOMONTH(in_FirstShip,0)=EOMONTH(F$23,0),in_WaitSize*in_WaitConv*$B$4,0) | G27: =IF(EOMONTH(in_FirstShip,0)=EOMONTH(G$23,0),in_WaitSize*in_WaitConv*$B$4,0) | H27: =IF(EOMONTH(in_FirstShip,0)=EOMONTH(H$23,0),in_WaitSize*in_WaitConv*$B$4,0) | I27: =IF(EOMONTH(in_FirstShip,0)=EOMONTH(I$23,0),in_WaitSize*in_WaitConv*$B$4,0) | J27: =IF(EOMONTH(in_FirstShip,0)=EOMONTH(J$23,0),in_WaitSize*in_WaitConv*$B$4,0) | ... Q27: =IF(EOMONTH(in_FirstShip,0)=EOMONTH(Q$23,0),in_WaitSize*in_WaitConv*$B$4,0) | R27: =SUM(C27:Q27)
A28: Organic new customers | C28: =IFERROR(INDEX(Inputs!$B$98:$B$107,MATCH(C$23,Inputs!$A$98:$A$107,0)),0)*$B$4*C24 | D28: =IFERROR(INDEX(Inputs!$B$98:$B$107,MATCH(D$23,Inputs!$A$98:$A$107,0)),0)*$B$4*D24 | E28: =IFERROR(INDEX(Inputs!$B$98:$B$107,MATCH(E$23,Inputs!$A$98:$A$107,0)),0)*$B$4*E24 | F28: =IFERROR(INDEX(Inputs!$B$98:$B$107,MATCH(F$23,Inputs!$A$98:$A$107,0)),0)*$B$4*F24 | G28: =IFERROR(INDEX(Inputs!$B$98:$B$107,MATCH(G$23,Inputs!$A$98:$A$107,0)),0)*$B$4*G24 | H28: =IFERROR(INDEX(Inputs!$B$98:$B$107,MATCH(H$23,Inputs!$A$98:$A$107,0)),0)*$B$4*H24 | I28: =IFERROR(INDEX(Inputs!$B$98:$B$107,MATCH(I$23,Inputs!$A$98:$A$107,0)),0)*$B$4*I24 | J28: =IFERROR(INDEX(Inputs!$B$98:$B$107,MATCH(J$23,Inputs!$A$98:$A$107,0)),0)*$B$4*J24 | ... Q28: =IFERROR(INDEX(Inputs!$B$98:$B$107,MATCH(Q$23,Inputs!$A$98:$A$107,0)),0)*$B$4*Q24 | R28: =SUM(C28:Q28)
A29: Paid new customers | C29: =IFERROR(INDEX(Inputs!$C$98:$C$107,MATCH(C$23,Inputs!$A$98:$A$107,0)),0)*$B$4*C24 | D29: =IFERROR(INDEX(Inputs!$C$98:$C$107,MATCH(D$23,Inputs!$A$98:$A$107,0)),0)*$B$4*D24 | E29: =IFERROR(INDEX(Inputs!$C$98:$C$107,MATCH(E$23,Inputs!$A$98:$A$107,0)),0)*$B$4*E24 | F29: =IFERROR(INDEX(Inputs!$C$98:$C$107,MATCH(F$23,Inputs!$A$98:$A$107,0)),0)*$B$4*F24 | G29: =IFERROR(INDEX(Inputs!$C$98:$C$107,MATCH(G$23,Inputs!$A$98:$A$107,0)),0)*$B$4*G24 | H29: =IFERROR(INDEX(Inputs!$C$98:$C$107,MATCH(H$23,Inputs!$A$98:$A$107,0)),0)*$B$4*H24 | I29: =IFERROR(INDEX(Inputs!$C$98:$C$107,MATCH(I$23,Inputs!$A$98:$A$107,0)),0)*$B$4*I24 | J29: =IFERROR(INDEX(Inputs!$C$98:$C$107,MATCH(J$23,Inputs!$A$98:$A$107,0)),0)*$B$4*J24 | ... Q29: =IFERROR(INDEX(Inputs!$C$98:$C$107,MATCH(Q$23,Inputs!$A$98:$A$107,0)),0)*$B$4*Q24 | R29: =SUM(C29:Q29)
A30: Total new DTC customers | C30: =C27+C28+C29 | D30: =D27+D28+D29 | E30: =E27+E28+E29 | F30: =F27+F28+F29 | G30: =G27+G28+G29 | H30: =H27+H28+H29 | I30: =I27+I28+I29 | J30: =J27+J28+J29 | ... Q30: =Q27+Q28+Q29 | R30: =SUM(C30:Q30)
A31: New subscribers | C31: =C30*in_SubShare | D31: =D30*in_SubShare | E31: =E30*in_SubShare | F31: =F30*in_SubShare | G31: =G30*in_SubShare | H31: =H30*in_SubShare | I31: =I30*in_SubShare | J31: =J30*in_SubShare | ... Q31: =Q30*in_SubShare | R31: =SUM(C31:Q31)
A32: Active subscribers, end of month (= subscription orders) | B32: 1 pouch/month each | C32: =C31 | D32: =C32*(1-in_SubChurn)+D31 | E32: =D32*(1-in_SubChurn)+E31 | F32: =E32*(1-in_SubChurn)+F31 | G32: =F32*(1-in_SubChurn)+G31 | H32: =G32*(1-in_SubChurn)+H31 | I32: =H32*(1-in_SubChurn)+I31 | J32: =I32*(1-in_SubChurn)+J31 | K32: =J32*(1-in_SubChurn)+K31 | ... Q32: =P32*(1-in_SubChurn)+Q31
A33: One-off first orders | C33: =C30*(1-in_SubShare) | D33: =D30*(1-in_SubShare) | E33: =E30*(1-in_SubShare) | F33: =F30*(1-in_SubShare) | G33: =G30*(1-in_SubShare) | H33: =H30*(1-in_SubShare) | I33: =I30*(1-in_SubShare) | J33: =J30*(1-in_SubShare) | ... Q33: =Q30*(1-in_SubShare) | R33: =SUM(C33:Q33)
A34: One-off repeat orders | C34: =0 | D34: =C35*in_Repeat | E34: =D35*in_Repeat | F34: =E35*in_Repeat | G34: =F35*in_Repeat | H34: =G35*in_Repeat | I34: =H35*in_Repeat | J34: =I35*in_Repeat | K34: =J35*in_Repeat | ... Q34: =P35*in_Repeat | R34: =SUM(C34:Q34)
A35: Total one-off pouch orders | C35: =C33+C34 | D35: =D33+D34 | E35: =E33+E34 | F35: =F33+F34 | G35: =G33+G34 | H35: =H33+H34 | I35: =I33+I34 | J35: =J33+J34 | ... Q35: =Q33+Q34 | R35: =SUM(C35:Q35)
A36: Total DTC pouch orders (one-off + subscription) | C36: =C35+C32 | D36: =D35+D32 | E36: =E35+E32 | F36: =F35+F32 | G36: =G35+G32 | H36: =H35+H32 | I36: =I35+I32 | J36: =J35+J32 | ... Q36: =Q35+Q32 | R36: =SUM(C36:Q36)
A37: DTC stick-box orders | C37: =C36*in_StickAttach | D37: =D36*in_StickAttach | E37: =E36*in_StickAttach | F37: =F36*in_StickAttach | G37: =G36*in_StickAttach | H37: =H36*in_StickAttach | I37: =I36*in_StickAttach | J37: =J36*in_StickAttach | ... Q37: =Q36*in_StickAttach | R37: =SUM(C37:Q37)
A39: Wholesale (direct to stores)
A40: New store accounts | C40: =IFERROR(INDEX(Inputs!$D$98:$D$107,MATCH(C$23,Inputs!$A$98:$A$107,0)),0)*$B$4*C24 | D40: =IFERROR(INDEX(Inputs!$D$98:$D$107,MATCH(D$23,Inputs!$A$98:$A$107,0)),0)*$B$4*D24 | E40: =IFERROR(INDEX(Inputs!$D$98:$D$107,MATCH(E$23,Inputs!$A$98:$A$107,0)),0)*$B$4*E24 | F40: =IFERROR(INDEX(Inputs!$D$98:$D$107,MATCH(F$23,Inputs!$A$98:$A$107,0)),0)*$B$4*F24 | G40: =IFERROR(INDEX(Inputs!$D$98:$D$107,MATCH(G$23,Inputs!$A$98:$A$107,0)),0)*$B$4*G24 | H40: =IFERROR(INDEX(Inputs!$D$98:$D$107,MATCH(H$23,Inputs!$A$98:$A$107,0)),0)*$B$4*H24 | I40: =IFERROR(INDEX(Inputs!$D$98:$D$107,MATCH(I$23,Inputs!$A$98:$A$107,0)),0)*$B$4*I24 | J40: =IFERROR(INDEX(Inputs!$D$98:$D$107,MATCH(J$23,Inputs!$A$98:$A$107,0)),0)*$B$4*J24 | ... Q40: =IFERROR(INDEX(Inputs!$D$98:$D$107,MATCH(Q$23,Inputs!$A$98:$A$107,0)),0)*$B$4*Q24 | R40: =SUM(C40:Q40)
A41: Active store accounts, end of month | C41: =C40 | D41: =C41*(1-in_StoreChurn)+D40 | E41: =D41*(1-in_StoreChurn)+E40 | F41: =E41*(1-in_StoreChurn)+F40 | G41: =F41*(1-in_StoreChurn)+G40 | H41: =G41*(1-in_StoreChurn)+H40 | I41: =H41*(1-in_StoreChurn)+I40 | J41: =I41*(1-in_StoreChurn)+J40 | K41: =J41*(1-in_StoreChurn)+K40 | ... Q41: =P41*(1-in_StoreChurn)+Q40
A42: Wholesale pouches shipped | C42: =C41*in_PouchPerStore | D42: =D41*in_PouchPerStore | E42: =E41*in_PouchPerStore | F42: =F41*in_PouchPerStore | G42: =G41*in_PouchPerStore | H42: =H41*in_PouchPerStore | I42: =I41*in_PouchPerStore | J42: =J41*in_PouchPerStore | ... Q42: =Q41*in_PouchPerStore | R42: =SUM(C42:Q42)
A43: Wholesale sticks shipped | C43: =C41*in_StickPerStore | D43: =D41*in_StickPerStore | E43: =E41*in_StickPerStore | F43: =F41*in_StickPerStore | G43: =G41*in_StickPerStore | H43: =H41*in_StickPerStore | I43: =I41*in_StickPerStore | J43: =J41*in_StickPerStore | ... Q43: =Q41*in_StickPerStore | R43: =SUM(C43:Q43)
A45: Pouch inventory (units)
...

Sheet Scenarios
A1: Picked: scenarios
A2: Change the run-size toggle and the multipliers on Inputs. Each case runs its own full copy of the monthly model (hidden sheets calc_*), so all cases show at once. Cash balance = starting cash + cumulative net cash flow.
A3: Active run-size mode | B3: =in_Mode
A4: Starting cash | B4: =in_StartCash
A6: A. Demand cases under the active run-size mode
A7: Demand case | B7: Multiplier | C7: Cash balance end Jun 2027 | D7: Cash balance end Dec 2027 | E7: Lowest cash balance | F7: Lowest month | G7: Operating break-even month | H7: Cash payback month
A8: Low | B8: =in_MultLow | C8: =IF(in_Mode="Lean",'calc_Lean_Low'!$B$18,'calc_Standard_Low'!$B$18) | D8: =IF(in_Mode="Lean",'calc_Lean_Low'!$B$19,'calc_Standard_Low'!$B$19) | E8: =IF(in_Mode="Lean",'calc_Lean_Low'!$B$13,'calc_Standard_Low'!$B$13) | F8: =IF(in_Mode="Lean",'calc_Lean_Low'!$B$14,'calc_Standard_Low'!$B$14) | G8: =IF(in_Mode="Lean",'calc_Lean_Low'!$B$16,'calc_Standard_Low'!$B$16) | H8: =IF(in_Mode="Lean",'calc_Lean_Low'!$B$17,'calc_Standard_Low'!$B$17)
A9: Base | B9: =in_MultBase | C9: =IF(in_Mode="Lean",'calc_Lean_Base'!$B$18,'calc_Standard_Base'!$B$18) | D9: =IF(in_Mode="Lean",'calc_Lean_Base'!$B$19,'calc_Standard_Base'!$B$19) | E9: =IF(in_Mode="Lean",'calc_Lean_Base'!$B$13,'calc_Standard_Base'!$B$13) | F9: =IF(in_Mode="Lean",'calc_Lean_Base'!$B$14,'calc_Standard_Base'!$B$14) | G9: =IF(in_Mode="Lean",'calc_Lean_Base'!$B$16,'calc_Standard_Base'!$B$16) | H9: =IF(in_Mode="Lean",'calc_Lean_Base'!$B$17,'calc_Standard_Base'!$B$17)
A10: High | B10: =in_MultHigh | C10: =IF(in_Mode="Lean",'calc_Lean_High'!$B$18,'calc_Standard_High'!$B$18) | D10: =IF(in_Mode="Lean",'calc_Lean_High'!$B$19,'calc_Standard_High'!$B$19) | E10: =IF(in_Mode="Lean",'calc_Lean_High'!$B$13,'calc_Standard_High'!$B$13) | F10: =IF(in_Mode="Lean",'calc_Lean_High'!$B$14,'calc_Standard_High'!$B$14) | G10: =IF(in_Mode="Lean",'calc_Lean_High'!$B$16,'calc_Standard_High'!$B$16) | H10: =IF(in_Mode="Lean",'calc_Lean_High'!$B$17,'calc_Standard_High'!$B$17)
A12: B. Lean (144-unit runs) vs Standard (1,000-unit runs), every demand case
A13: Demand case | B13: Run size | C13: Cash balance end Jun 2027 | D13: Cash balance end Dec 2027 | E13: Lowest cash balance | F13: Lowest month | G13: Operating break-even month | H13: Peak funding need
A14: Low | B14: Lean | C14: ='calc_Lean_Low'!$B$18 | D14: ='calc_Lean_Low'!$B$19 | E14: ='calc_Lean_Low'!$B$13 | F14: ='calc_Lean_Low'!$B$14 | G14: ='calc_Lean_Low'!$B$16 | H14: ='calc_Lean_Low'!$B$15
A15: Low | B15: Standard | C15: ='calc_Standard_Low'!$B$18 | D15: ='calc_Standard_Low'!$B$19 | E15: ='calc_Standard_Low'!$B$13 | F15: ='calc_Standard_Low'!$B$14 | G15: ='calc_Standard_Low'!$B$16 | H15: ='calc_Standard_Low'!$B$15
A16: Base | B16: Lean | C16: ='calc_Lean_Base'!$B$18 | D16: ='calc_Lean_Base'!$B$19 | E16: ='calc_Lean_Base'!$B$13 | F16: ='calc_Lean_Base'!$B$14 | G16: ='calc_Lean_Base'!$B$16 | H16: ='calc_Lean_Base'!$B$15
A17: Base | B17: Standard | C17: ='calc_Standard_Base'!$B$18 | D17: ='calc_Standard_Base'!$B$19 | E17: ='calc_Standard_Base'!$B$13 | F17: ='calc_Standard_Base'!$B$14 | G17: ='calc_Standard_Base'!$B$16 | H17: ='calc_Standard_Base'!$B$15
A18: High | B18: Lean | C18: ='calc_Lean_High'!$B$18 | D18: ='calc_Lean_High'!$B$19 | E18: ='calc_Lean_High'!$B$13 | F18: ='calc_Lean_High'!$B$14 | G18: ='calc_Lean_High'!$B$16 | H18: ='calc_Lean_High'!$B$15
A19: High | B19: Standard | C19: ='calc_Standard_High'!$B$18 | D19: ='calc_Standard_High'!$B$19 | E19: ='calc_Standard_High'!$B$13 | F19: ='calc_Standard_High'!$B$14 | G19: ='calc_Standard_High'!$B$16 | H19: ='calc_Standard_High'!$B$15
A21: Operating break-even = first month operating profit (revenue - COGS on units sold - variable - marketing - fixed) is zero or better; launch costs and inventory build are excluded. Cash payback = first month cumulative net cash flow returns to zero. Peak funding need = the most cash out before money comes back.

Sheet calc_Lean_Low
A1: Calculation copy: Lean runs, Low demand (feeds Scenarios; do not edit)
A2: Months Oct 2026 to Dec 2027. All figures are projections from the Inputs sheet, not actual results. Cash view: inventory is a cash outflow when bought; COGS appears only in the operating view at the bottom.
A3: Run-size mode | B3: ="Lean"
A4: Demand multiplier | B4: =in_MultLow
A5: Demand case | B5: ="Low"
A6: Pouch cost of goods (by mode) | B6: =IF($B$3="Lean",in_CogsLean,in_CogsStd)
A7: Stick cost of goods (by mode) | B7: =IF($B$3="Lean",in_StickCogsLean,in_StickCogsStd)
A8: Pouch run size (by mode) | B8: =IF($B$3="Lean",in_RunLean,in_RunStd)
A9: Stick run size (by mode) | B9: =IF($B$3="Lean",in_StickRunLean,in_StickRunStd)
A10: Sample credit on first order (by mode) | B10: =IF($B$3="Lean",in_SampleCreditLean,in_SampleCreditStd)
A12: Summary for this sheet's mode and case
A13: Lowest cash balance | B13: =MIN($C$120:$Q$120)
A14: Month of lowest cash balance | B14: =INDEX($C$23:$Q$23,MATCH(MIN($C$120:$Q$120),$C$120:$Q$120,0))
A15: Peak funding need (lowest cumulative net cash flow) | B15: =MIN(0,MIN($C$119:$Q$119))
A16: Operating break-even month (first month operating profit >= 0) | B16: =IFERROR(INDEX($C$23:$Q$23,MATCH(1,$C$127:$Q$127,0)),"Not by Dec 2027")
A17: Cash payback month (cumulative net cash flow back to >= 0) | B17: =IFERROR(INDEX($C$23:$Q$23,MATCH(1,$C$128:$Q$128,0)),"Not by Dec 2027")
A18: Cash balance, end of Jun 2027 | B18: =IFERROR(INDEX($C$120:$Q$120,MATCH(DATE(2027,6,1),$C$23:$Q$23,0)),"n/a")
A19: Cash balance, end of Dec 2027 | B19: =IFERROR(INDEX($C$120:$Q$120,MATCH(DATE(2027,12,1),$C$23:$Q$23,0)),"n/a")
A20: Stockout check (pouch + stick units short; should be 0) | B20: =SUM($C$54:$Q$54)+SUM($C$65:$Q$65)
A21: Operating profit, Oct 2026 to Dec 2027 (launch costs excluded) | B21: =SUM($C$126:$Q$126)
A23: Line | B23: Note | C23: =DATE(YEAR(in_ModelStart),MONTH(in_ModelStart),1) | D23: =EDATE(C23,1) | E23: =EDATE(D23,1) | F23: =EDATE(E23,1) | G23: =EDATE(F23,1) | H23: =EDATE(G23,1) | I23: =EDATE(H23,1) | J23: =EDATE(I23,1) | K23: =EDATE(J23,1) | ... Q23: =EDATE(P23,1) | R23: Total
A24: Selling? (1 from the first ship month) | C24: =IF(C$23>=DATE(YEAR(in_FirstShip),MONTH(in_FirstShip),1),1,0) | D24: =IF(D$23>=DATE(YEAR(in_FirstShip),MONTH(in_FirstShip),1),1,0) | E24: =IF(E$23>=DATE(YEAR(in_FirstShip),MONTH(in_FirstShip),1),1,0) | F24: =IF(F$23>=DATE(YEAR(in_FirstShip),MONTH(in_FirstShip),1),1,0) | G24: =IF(G$23>=DATE(YEAR(in_FirstShip),MONTH(in_FirstShip),1),1,0) | H24: =IF(H$23>=DATE(YEAR(in_FirstShip),MONTH(in_FirstShip),1),1,0) | I24: =IF(I$23>=DATE(YEAR(in_FirstShip),MONTH(in_FirstShip),1),1,0) | J24: =IF(J$23>=DATE(YEAR(in_FirstShip),MONTH(in_FirstShip),1),1,0) | ... Q24: =IF(Q$23>=DATE(YEAR(in_FirstShip),MONTH(in_FirstShip),1),1,0)
A26: DTC customers and orders
A27: Waitlist first orders (first ship month only) | B27: Waitlist x conversion | C27: =IF(EOMONTH(in_FirstShip,0)=EOMONTH(C$23,0),in_WaitSize*in_WaitConv*$B$4,0) | D27: =IF(EOMONTH(in_FirstShip,0)=EOMONTH(D$23,0),in_WaitSize*in_WaitConv*$B$4,0) | E27: =IF(EOMONTH(in_FirstShip,0)=EOMONTH(E$23,0),in_WaitSize*in_WaitConv*$B$4,0) | F27: =IF(EOMONTH(in_FirstShip,0)=EOMONTH(F$23,0),in_WaitSize*in_WaitConv*$B$4,0) | G27: =IF(EOMONTH(in_FirstShip,0)=EOMONTH(G$23,0),in_WaitSize*in_WaitConv*$B$4,0) | H27: =IF(EOMONTH(in_FirstShip,0)=EOMONTH(H$23,0),in_WaitSize*in_WaitConv*$B$4,0) | I27: =IF(EOMONTH(in_FirstShip,0)=EOMONTH(I$23,0),in_WaitSize*in_WaitConv*$B$4,0) | J27: =IF(EOMONTH(in_FirstShip,0)=EOMONTH(J$23,0),in_WaitSize*in_WaitConv*$B$4,0) | ... Q27: =IF(EOMONTH(in_FirstShip,0)=EOMONTH(Q$23,0),in_WaitSize*in_WaitConv*$B$4,0) | R27: =SUM(C27:Q27)
A28: Organic new customers | C28: =IFERROR(INDEX(Inputs!$B$98:$B$107,MATCH(C$23,Inputs!$A$98:$A$107,0)),0)*$B$4*C24 | D28: =IFERROR(INDEX(Inputs!$B$98:$B$107,MATCH(D$23,Inputs!$A$98:$A$107,0)),0)*$B$4*D24 | E28: =IFERROR(INDEX(Inputs!$B$98:$B$107,MATCH(E$23,Inputs!$A$98:$A$107,0)),0)*$B$4*E24 | F28: =IFERROR(INDEX(Inputs!$B$98:$B$107,MATCH(F$23,Inputs!$A$98:$A$107,0)),0)*$B$4*F24 | G28: =IFERROR(INDEX(Inputs!$B$98:$B$107,MATCH(G$23,Inputs!$A$98:$A$107,0)),0)*$B$4*G24 | H28: =IFERROR(INDEX(Inputs!$B$98:$B$107,MATCH(H$23,Inputs!$A$98:$A$107,0)),0)*$B$4*H24 | I28: =IFERROR(INDEX(Inputs!$B$98:$B$107,MATCH(I$23,Inputs!$A$98:$A$107,0)),0)*$B$4*I24 | J28: =IFERROR(INDEX(Inputs!$B$98:$B$107,MATCH(J$23,Inputs!$A$98:$A$107,0)),0)*$B$4*J24 | ... Q28: =IFERROR(INDEX(Inputs!$B$98:$B$107,MATCH(Q$23,Inputs!$A$98:$A$107,0)),0)*$B$4*Q24 | R28: =SUM(C28:Q28)
A29: Paid new customers | C29: =IFERROR(INDEX(Inputs!$C$98:$C$107,MATCH(C$23,Inputs!$A$98:$A$107,0)),0)*$B$4*C24 | D29: =IFERROR(INDEX(Inputs!$C$98:$C$107,MATCH(D$23,Inputs!$A$98:$A$107,0)),0)*$B$4*D24 | E29: =IFERROR(INDEX(Inputs!$C$98:$C$107,MATCH(E$23,Inputs!$A$98:$A$107,0)),0)*$B$4*E24 | F29: =IFERROR(INDEX(Inputs!$C$98:$C$107,MATCH(F$23,Inputs!$A$98:$A$107,0)),0)*$B$4*F24 | G29: =IFERROR(INDEX(Inputs!$C$98:$C$107,MATCH(G$23,Inputs!$A$98:$A$107,0)),0)*$B$4*G24 | H29: =IFERROR(INDEX(Inputs!$C$98:$C$107,MATCH(H$23,Inputs!$A$98:$A$107,0)),0)*$B$4*H24 | I29: =IFERROR(INDEX(Inputs!$C$98:$C$107,MATCH(I$23,Inputs!$A$98:$A$107,0)),0)*$B$4*I24 | J29: =IFERROR(INDEX(Inputs!$C$98:$C$107,MATCH(J$23,Inputs!$A$98:$A$107,0)),0)*$B$4*J24 | ... Q29: =IFERROR(INDEX(Inputs!$C$98:$C$107,MATCH(Q$23,Inputs!$A$98:$A$107,0)),0)*$B$4*Q24 | R29: =SUM(C29:Q29)
A30: Total new DTC customers | C30: =C27+C28+C29 | D30: =D27+D28+D29 | E30: =E27+E28+E29 | F30: =F27+F28+F29 | G30: =G27+G28+G29 | H30: =H27+H28+H29 | I30: =I27+I28+I29 | J30: =J27+J28+J29 | ... Q30: =Q27+Q28+Q29 | R30: =SUM(C30:Q30)
A31: New subscribers | C31: =C30*in_SubShare | D31: =D30*in_SubShare | E31: =E30*in_SubShare | F31: =F30*in_SubShare | G31: =G30*in_SubShare | H31: =H30*in_SubShare | I31: =I30*in_SubShare | J31: =J30*in_SubShare | ... Q31: =Q30*in_SubShare | R31: =SUM(C31:Q31)
A32: Active subscribers, end of month (= subscription orders) | B32: 1 pouch/month each | C32: =C31 | D32: =C32*(1-in_SubChurn)+D31 | E32: =D32*(1-in_SubChurn)+E31 | F32: =E32*(1-in_SubChurn)+F31 | G32: =F32*(1-in_SubChurn)+G31 | H32: =G32*(1-in_SubChurn)+H31 | I32: =H32*(1-in_SubChurn)+I31 | J32: =I32*(1-in_SubChurn)+J31 | K32: =J32*(1-in_SubChurn)+K31 | ... Q32: =P32*(1-in_SubChurn)+Q31
A33: One-off first orders | C33: =C30*(1-in_SubShare) | D33: =D30*(1-in_SubShare) | E33: =E30*(1-in_SubShare) | F33: =F30*(1-in_SubShare) | G33: =G30*(1-in_SubShare) | H33: =H30*(1-in_SubShare) | I33: =I30*(1-in_SubShare) | J33: =J30*(1-in_SubShare) | ... Q33: =Q30*(1-in_SubShare) | R33: =SUM(C33:Q33)
A34: One-off repeat orders | C34: =0 | D34: =C35*in_Repeat | E34: =D35*in_Repeat | F34: =E35*in_Repeat | G34: =F35*in_Repeat | H34: =G35*in_Repeat | I34: =H35*in_Repeat | J34: =I35*in_Repeat | K34: =J35*in_Repeat | ... Q34: =P35*in_Repeat | R34: =SUM(C34:Q34)
A35: Total one-off pouch orders | C35: =C33+C34 | D35: =D33+D34 | E35: =E33+E34 | F35: =F33+F34 | G35: =G33+G34 | H35: =H33+H34 | I35: =I33+I34 | J35: =J33+J34 | ... Q35: =Q33+Q34 | R35: =SUM(C35:Q35)
A36: Total DTC pouch orders (one-off + subscription) | C36: =C35+C32 | D36: =D35+D32 | E36: =E35+E32 | F36: =F35+F32 | G36: =G35+G32 | H36: =H35+H32 | I36: =I35+I32 | J36: =J35+J32 | ... Q36: =Q35+Q32 | R36: =SUM(C36:Q36)
A37: DTC stick-box orders | C37: =C36*in_StickAttach | D37: =D36*in_StickAttach | E37: =E36*in_StickAttach | F37: =F36*in_StickAttach | G37: =G36*in_StickAttach | H37: =H36*in_StickAttach | I37: =I36*in_StickAttach | J37: =J36*in_StickAttach | ... Q37: =Q36*in_StickAttach | R37: =SUM(C37:Q37)
A39: Wholesale (direct to stores)
A40: New store accounts | C40: =IFERROR(INDEX(Inputs!$D$98:$D$107,MATCH(C$23,Inputs!$A$98:$A$107,0)),0)*$B$4*C24 | D40: =IFERROR(INDEX(Inputs!$D$98:$D$107,MATCH(D$23,Inputs!$A$98:$A$107,0)),0)*$B$4*D24 | E40: =IFERROR(INDEX(Inputs!$D$98:$D$107,MATCH(E$23,Inputs!$A$98:$A$107,0)),0)*$B$4*E24 | F40: =IFERROR(INDEX(Inputs!$D$98:$D$107,MATCH(F$23,Inputs!$A$98:$A$107,0)),0)*$B$4*F24 | G40: =IFERROR(INDEX(Inputs!$D$98:$D$107,MATCH(G$23,Inputs!$A$98:$A$107,0)),0)*$B$4*G24 | H40: =IFERROR(INDEX(Inputs!$D$98:$D$107,MATCH(H$23,Inputs!$A$98:$A$107,0)),0)*$B$4*H24 | I40: =IFERROR(INDEX(Inputs!$D$98:$D$107,MATCH(I$23,Inputs!$A$98:$A$107,0)),0)*$B$4*I24 | J40: =IFERROR(INDEX(Inputs!$D$98:$D$107,MATCH(J$23,Inputs!$A$98:$A$107,0)),0)*$B$4*J24 | ... Q40: =IFERROR(INDEX(Inputs!$D$98:$D$107,MATCH(Q$23,Inputs!$A$98:$A$107,0)),0)*$B$4*Q24 | R40: =SUM(C40:Q40)
A41: Active store accounts, end of month | C41: =C40 | D41: =C41*(1-in_StoreChurn)+D40 | E41: =D41*(1-in_StoreChurn)+E40 | F41: =E41*(1-in_StoreChurn)+F40 | G41: =F41*(1-in_StoreChurn)+G40 | H41: =G41*(1-in_StoreChurn)+H40 | I41: =H41*(1-in_StoreChurn)+I40 | J41: =I41*(1-in_StoreChurn)+J40 | K41: =J41*(1-in_StoreChurn)+K40 | ... Q41: =P41*(1-in_StoreChurn)+Q40
A42: Wholesale pouches shipped | C42: =C41*in_PouchPerStore | D42: =D41*in_PouchPerStore | E42: =E41*in_PouchPerStore | F42: =F41*in_PouchPerStore | G42: =G41*in_PouchPerStore | H42: =H41*in_PouchPerStore | I42: =I41*in_PouchPerStore | J42: =J41*in_PouchPerStore | ... Q42: =Q41*in_PouchPerStore | R42: =SUM(C42:Q42)
A43: Wholesale sticks shipped | C43: =C41*in_StickPerStore | D43: =D41*in_StickPerStore | E43: =E41*in_StickPerStore | F43: =F41*in_StickPerStore | G43: =G41*in_StickPerStore | H43: =H41*in_StickPerStore | I43: =I41*in_StickPerStore | J43: =J41*in_StickPerStore | ... Q43: =Q41*in_StickPerStore | R43: =SUM(C43:Q43)
A45: Pouch inventory (units)
...

Sheet calc_Lean_Base
A1: Calculation copy: Lean runs, Base demand (feeds Scenarios; do not edit)
A2: Months Oct 2026 to Dec 2027. All figures are projections from the Inputs sheet, not actual results. Cash view: inventory is a cash outflow when bought; COGS appears only in the operating view at the bottom.
A3: Run-size mode | B3: ="Lean"
A4: Demand multiplier | B4: =in_MultBase
A5: Demand case | B5: ="Base"
A6: Pouch cost of goods (by mode) | B6: =IF($B$3="Lean",in_CogsLean,in_CogsStd)
A7: Stick cost of goods (by mode) | B7: =IF($B$3="Lean",in_StickCogsLean,in_StickCogsStd)
A8: Pouch run size (by mode) | B8: =IF($B$3="Lean",in_RunLean,in_RunStd)
A9: Stick run size (by mode) | B9: =IF($B$3="Lean",in_StickRunLean,in_StickRunStd)
A10: Sample credit on first order (by mode) | B10: =IF($B$3="Lean",in_SampleCreditLean,in_SampleCreditStd)
A12: Summary for this sheet's mode and case
A13: Lowest cash balance | B13: =MIN($C$120:$Q$120)
A14: Month of lowest cash balance | B14: =INDEX($C$23:$Q$23,MATCH(MIN($C$120:$Q$120),$C$120:$Q$120,0))
A15: Peak funding need (lowest cumulative net cash flow) | B15: =MIN(0,MIN($C$119:$Q$119))
A16: Operating break-even month (first month operating profit >= 0) | B16: =IFERROR(INDEX($C$23:$Q$23,MATCH(1,$C$127:$Q$127,0)),"Not by Dec 2027")
A17: Cash payback month (cumulative net cash flow back to >= 0) | B17: =IFERROR(INDEX($C$23:$Q$23,MATCH(1,$C$128:$Q$128,0)),"Not by Dec 2027")
A18: Cash balance, end of Jun 2027 | B18: =IFERROR(INDEX($C$120:$Q$120,MATCH(DATE(2027,6,1),$C$23:$Q$23,0)),"n/a")
A19: Cash balance, end of Dec 2027 | B19: =IFERROR(INDEX($C$120:$Q$120,MATCH(DATE(2027,12,1),$C$23:$Q$23,0)),"n/a")
A20: Stockout check (pouch + stick units short; should be 0) | B20: =SUM($C$54:$Q$54)+SUM($C$65:$Q$65)
A21: Operating profit, Oct 2026 to Dec 2027 (launch costs excluded) | B21: =SUM($C$126:$Q$126)
A23: Line | B23: Note | C23: =DATE(YEAR(in_ModelStart),MONTH(in_ModelStart),1) | D23: =EDATE(C23,1) | E23: =EDATE(D23,1) | F23: =EDATE(E23,1) | G23: =EDATE(F23,1) | H23: =EDATE(G23,1) | I23: =EDATE(H23,1) | J23: =EDATE(I23,1) | K23: =EDATE(J23,1) | ... Q23: =EDATE(P23,1) | R23: Total
A24: Selling? (1 from the first ship month) | C24: =IF(C$23>=DATE(YEAR(in_FirstShip),MONTH(in_FirstShip),1),1,0) | D24: =IF(D$23>=DATE(YEAR(in_FirstShip),MONTH(in_FirstShip),1),1,0) | E24: =IF(E$23>=DATE(YEAR(in_FirstShip),MONTH(in_FirstShip),1),1,0) | F24: =IF(F$23>=DATE(YEAR(in_FirstShip),MONTH(in_FirstShip),1),1,0) | G24: =IF(G$23>=DATE(YEAR(in_FirstShip),MONTH(in_FirstShip),1),1,0) | H24: =IF(H$23>=DATE(YEAR(in_FirstShip),MONTH(in_FirstShip),1),1,0) | I24: =IF(I$23>=DATE(YEAR(in_FirstShip),MONTH(in_FirstShip),1),1,0) | J24: =IF(J$23>=DATE(YEAR(in_FirstShip),MONTH(in_FirstShip),1),1,0) | ... Q24: =IF(Q$23>=DATE(YEAR(in_FirstShip),MONTH(in_FirstShip),1),1,0)
A26: DTC customers and orders
A27: Waitlist first orders (first ship month only) | B27: Waitlist x conversion | C27: =IF(EOMONTH(in_FirstShip,0)=EOMONTH(C$23,0),in_WaitSize*in_WaitConv*$B$4,0) | D27: =IF(EOMONTH(in_FirstShip,0)=EOMONTH(D$23,0),in_WaitSize*in_WaitConv*$B$4,0) | E27: =IF(EOMONTH(in_FirstShip,0)=EOMONTH(E$23,0),in_WaitSize*in_WaitConv*$B$4,0) | F27: =IF(EOMONTH(in_FirstShip,0)=EOMONTH(F$23,0),in_WaitSize*in_WaitConv*$B$4,0) | G27: =IF(EOMONTH(in_FirstShip,0)=EOMONTH(G$23,0),in_WaitSize*in_WaitConv*$B$4,0) | H27: =IF(EOMONTH(in_FirstShip,0)=EOMONTH(H$23,0),in_WaitSize*in_WaitConv*$B$4,0) | I27: =IF(EOMONTH(in_FirstShip,0)=EOMONTH(I$23,0),in_WaitSize*in_WaitConv*$B$4,0) | J27: =IF(EOMONTH(in_FirstShip,0)=EOMONTH(J$23,0),in_WaitSize*in_WaitConv*$B$4,0) | ... Q27: =IF(EOMONTH(in_FirstShip,0)=EOMONTH(Q$23,0),in_WaitSize*in_WaitConv*$B$4,0) | R27: =SUM(C27:Q27)
A28: Organic new customers | C28: =IFERROR(INDEX(Inputs!$B$98:$B$107,MATCH(C$23,Inputs!$A$98:$A$107,0)),0)*$B$4*C24 | D28: =IFERROR(INDEX(Inputs!$B$98:$B$107,MATCH(D$23,Inputs!$A$98:$A$107,0)),0)*$B$4*D24 | E28: =IFERROR(INDEX(Inputs!$B$98:$B$107,MATCH(E$23,Inputs!$A$98:$A$107,0)),0)*$B$4*E24 | F28: =IFERROR(INDEX(Inputs!$B$98:$B$107,MATCH(F$23,Inputs!$A$98:$A$107,0)),0)*$B$4*F24 | G28: =IFERROR(INDEX(Inputs!$B$98:$B$107,MATCH(G$23,Inputs!$A$98:$A$107,0)),0)*$B$4*G24 | H28: =IFERROR(INDEX(Inputs!$B$98:$B$107,MATCH(H$23,Inputs!$A$98:$A$107,0)),0)*$B$4*H24 | I28: =IFERROR(INDEX(Inputs!$B$98:$B$107,MATCH(I$23,Inputs!$A$98:$A$107,0)),0)*$B$4*I24 | J28: =IFERROR(INDEX(Inputs!$B$98:$B$107,MATCH(J$23,Inputs!$A$98:$A$107,0)),0)*$B$4*J24 | ... Q28: =IFERROR(INDEX(Inputs!$B$98:$B$107,MATCH(Q$23,Inputs!$A$98:$A$107,0)),0)*$B$4*Q24 | R28: =SUM(C28:Q28)
A29: Paid new customers | C29: =IFERROR(INDEX(Inputs!$C$98:$C$107,MATCH(C$23,Inputs!$A$98:$A$107,0)),0)*$B$4*C24 | D29: =IFERROR(INDEX(Inputs!$C$98:$C$107,MATCH(D$23,Inputs!$A$98:$A$107,0)),0)*$B$4*D24 | E29: =IFERROR(INDEX(Inputs!$C$98:$C$107,MATCH(E$23,Inputs!$A$98:$A$107,0)),0)*$B$4*E24 | F29: =IFERROR(INDEX(Inputs!$C$98:$C$107,MATCH(F$23,Inputs!$A$98:$A$107,0)),0)*$B$4*F24 | G29: =IFERROR(INDEX(Inputs!$C$98:$C$107,MATCH(G$23,Inputs!$A$98:$A$107,0)),0)*$B$4*G24 | H29: =IFERROR(INDEX(Inputs!$C$98:$C$107,MATCH(H$23,Inputs!$A$98:$A$107,0)),0)*$B$4*H24 | I29: =IFERROR(INDEX(Inputs!$C$98:$C$107,MATCH(I$23,Inputs!$A$98:$A$107,0)),0)*$B$4*I24 | J29: =IFERROR(INDEX(Inputs!$C$98:$C$107,MATCH(J$23,Inputs!$A$98:$A$107,0)),0)*$B$4*J24 | ... Q29: =IFERROR(INDEX(Inputs!$C$98:$C$107,MATCH(Q$23,Inputs!$A$98:$A$107,0)),0)*$B$4*Q24 | R29: =SUM(C29:Q29)
A30: Total new DTC customers | C30: =C27+C28+C29 | D30: =D27+D28+D29 | E30: =E27+E28+E29 | F30: =F27+F28+F29 | G30: =G27+G28+G29 | H30: =H27+H28+H29 | I30: =I27+I28+I29 | J30: =J27+J28+J29 | ... Q30: =Q27+Q28+Q29 | R30: =SUM(C30:Q30)
A31: New subscribers | C31: =C30*in_SubShare | D31: =D30*in_SubShare | E31: =E30*in_SubShare | F31: =F30*in_SubShare | G31: =G30*in_SubShare | H31: =H30*in_SubShare | I31: =I30*in_SubShare | J31: =J30*in_SubShare | ... Q31: =Q30*in_SubShare | R31: =SUM(C31:Q31)
A32: Active subscribers, end of month (= subscription orders) | B32: 1 pouch/month each | C32: =C31 | D32: =C32*(1-in_SubChurn)+D31 | E32: =D32*(1-in_SubChurn)+E31 | F32: =E32*(1-in_SubChurn)+F31 | G32: =F32*(1-in_SubChurn)+G31 | H32: =G32*(1-in_SubChurn)+H31 | I32: =H32*(1-in_SubChurn)+I31 | J32: =I32*(1-in_SubChurn)+J31 | K32: =J32*(1-in_SubChurn)+K31 | ... Q32: =P32*(1-in_SubChurn)+Q31
A33: One-off first orders | C33: =C30*(1-in_SubShare) | D33: =D30*(1-in_SubShare) | E33: =E30*(1-in_SubShare) | F33: =F30*(1-in_SubShare) | G33: =G30*(1-in_SubShare) | H33: =H30*(1-in_SubShare) | I33: =I30*(1-in_SubShare) | J33: =J30*(1-in_SubShare) | ... Q33: =Q30*(1-in_SubShare) | R33: =SUM(C33:Q33)
A34: One-off repeat orders | C34: =0 | D34: =C35*in_Repeat | E34: =D35*in_Repeat | F34: =E35*in_Repeat | G34: =F35*in_Repeat | H34: =G35*in_Repeat | I34: =H35*in_Repeat | J34: =I35*in_Repeat | K34: =J35*in_Repeat | ... Q34: =P35*in_Repeat | R34: =SUM(C34:Q34)
A35: Total one-off pouch orders | C35: =C33+C34 | D35: =D33+D34 | E35: =E33+E34 | F35: =F33+F34 | G35: =G33+G34 | H35: =H33+H34 | I35: =I33+I34 | J35: =J33+J34 | ... Q35: =Q33+Q34 | R35: =SUM(C35:Q35)
A36: Total DTC pouch orders (one-off + subscription) | C36: =C35+C32 | D36: =D35+D32 | E36: =E35+E32 | F36: =F35+F32 | G36: =G35+G32 | H36: =H35+H32 | I36: =I35+I32 | J36: =J35+J32 | ... Q36: =Q35+Q32 | R36: =SUM(C36:Q36)
A37: DTC stick-box orders | C37: =C36*in_StickAttach | D37: =D36*in_StickAttach | E37: =E36*in_StickAttach | F37: =F36*in_StickAttach | G37: =G36*in_StickAttach | H37: =H36*in_StickAttach | I37: =I36*in_StickAttach | J37: =J36*in_StickAttach | ... Q37: =Q36*in_StickAttach | R37: =SUM(C37:Q37)
A39: Wholesale (direct to stores)
A40: New store accounts | C40: =IFERROR(INDEX(Inputs!$D$98:$D$107,MATCH(C$23,Inputs!$A$98:$A$107,0)),0)*$B$4*C24 | D40: =IFERROR(INDEX(Inputs!$D$98:$D$107,MATCH(D$23,Inputs!$A$98:$A$107,0)),0)*$B$4*D24 | E40: =IFERROR(INDEX(Inputs!$D$98:$D$107,MATCH(E$23,Inputs!$A$98:$A$107,0)),0)*$B$4*E24 | F40: =IFERROR(INDEX(Inputs!$D$98:$D$107,MATCH(F$23,Inputs!$A$98:$A$107,0)),0)*$B$4*F24 | G40: =IFERROR(INDEX(Inputs!$D$98:$D$107,MATCH(G$23,Inputs!$A$98:$A$107,0)),0)*$B$4*G24 | H40: =IFERROR(INDEX(Inputs!$D$98:$D$107,MATCH(H$23,Inputs!$A$98:$A$107,0)),0)*$B$4*H24 | I40: =IFERROR(INDEX(Inputs!$D$98:$D$107,MATCH(I$23,Inputs!$A$98:$A$107,0)),0)*$B$4*I24 | J40: =IFERROR(INDEX(Inputs!$D$98:$D$107,MATCH(J$23,Inputs!$A$98:$A$107,0)),0)*$B$4*J24 | ... Q40: =IFERROR(INDEX(Inputs!$D$98:$D$107,MATCH(Q$23,Inputs!$A$98:$A$107,0)),0)*$B$4*Q24 | R40: =SUM(C40:Q40)
A41: Active store accounts, end of month | C41: =C40 | D41: =C41*(1-in_StoreChurn)+D40 | E41: =D41*(1-in_StoreChurn)+E40 | F41: =E41*(1-in_StoreChurn)+F40 | G41: =F41*(1-in_StoreChurn)+G40 | H41: =G41*(1-in_StoreChurn)+H40 | I41: =H41*(1-in_StoreChurn)+I40 | J41: =I41*(1-in_StoreChurn)+J40 | K41: =J41*(1-in_StoreChurn)+K40 | ... Q41: =P41*(1-in_StoreChurn)+Q40
A42: Wholesale pouches shipped | C42: =C41*in_PouchPerStore | D42: =D41*in_PouchPerStore | E42: =E41*in_PouchPerStore | F42: =F41*in_PouchPerStore | G42: =G41*in_PouchPerStore | H42: =H41*in_PouchPerStore | I42: =I41*in_PouchPerStore | J42: =J41*in_PouchPerStore | ... Q42: =Q41*in_PouchPerStore | R42: =SUM(C42:Q42)
A43: Wholesale sticks shipped | C43: =C41*in_StickPerStore | D43: =D41*in_StickPerStore | E43: =E41*in_StickPerStore | F43: =F41*in_StickPerStore | G43: =G41*in_StickPerStore | H43: =H41*in_StickPerStore | I43: =I41*in_StickPerStore | J43: =J41*in_StickPerStore | ... Q43: =Q41*in_StickPerStore | R43: =SUM(C43:Q43)
A45: Pouch inventory (units)
...

Sheet calc_Lean_High
A1: Calculation copy: Lean runs, High demand (feeds Scenarios; do not edit)
A2: Months Oct 2026 to Dec 2027. All figures are projections from the Inputs sheet, not actual results. Cash view: inventory is a cash outflow when bought; COGS appears only in the operating view at the bottom.
A3: Run-size mode | B3: ="Lean"
A4: Demand multiplier | B4: =in_MultHigh
A5: Demand case | B5: ="High"
A6: Pouch cost of goods (by mode) | B6: =IF($B$3="Lean",in_CogsLean,in_CogsStd)
A7: Stick cost of goods (by mode) | B7: =IF($B$3="Lean",in_StickCogsLean,in_StickCogsStd)
A8: Pouch run size (by mode) | B8: =IF($B$3="Lean",in_RunLean,in_RunStd)
A9: Stick run size (by mode) | B9: =IF($B$3="Lean",in_StickRunLean,in_StickRunStd)
A10: Sample credit on first order (by mode) | B10: =IF($B$3="Lean",in_SampleCreditLean,in_SampleCreditStd)
A12: Summary for this sheet's mode and case
A13: Lowest cash balance | B13: =MIN($C$120:$Q$120)
A14: Month of lowest cash balance | B14: =INDEX($C$23:$Q$23,MATCH(MIN($C$120:$Q$120),$C$120:$Q$120,0))
A15: Peak funding need (lowest cumulative net cash flow) | B15: =MIN(0,MIN($C$119:$Q$119))
A16: Operating break-even month (first month operating profit >= 0) | B16: =IFERROR(INDEX($C$23:$Q$23,MATCH(1,$C$127:$Q$127,0)),"Not by Dec 2027")
A17: Cash payback month (cumulative net cash flow back to >= 0) | B17: =IFERROR(INDEX($C$23:$Q$23,MATCH(1,$C$128:$Q$128,0)),"Not by Dec 2027")
A18: Cash balance, end of Jun 2027 | B18: =IFERROR(INDEX($C$120:$Q$120,MATCH(DATE(2027,6,1),$C$23:$Q$23,0)),"n/a")
A19: Cash balance, end of Dec 2027 | B19: =IFERROR(INDEX($C$120:$Q$120,MATCH(DATE(2027,12,1),$C$23:$Q$23,0)),"n/a")
A20: Stockout check (pouch + stick units short; should be 0) | B20: =SUM($C$54:$Q$54)+SUM($C$65:$Q$65)
A21: Operating profit, Oct 2026 to Dec 2027 (launch costs excluded) | B21: =SUM($C$126:$Q$126)
A23: Line | B23: Note | C23: =DATE(YEAR(in_ModelStart),MONTH(in_ModelStart),1) | D23: =EDATE(C23,1) | E23: =EDATE(D23,1) | F23: =EDATE(E23,1) | G23: =EDATE(F23,1) | H23: =EDATE(G23,1) | I23: =EDATE(H23,1) | J23: =EDATE(I23,1) | K23: =EDATE(J23,1) | ... Q23: =EDATE(P23,1) | R23: Total
A24: Selling? (1 from the first ship month) | C24: =IF(C$23>=DATE(YEAR(in_FirstShip),MONTH(in_FirstShip),1),1,0) | D24: =IF(D$23>=DATE(YEAR(in_FirstShip),MONTH(in_FirstShip),1),1,0) | E24: =IF(E$23>=DATE(YEAR(in_FirstShip),MONTH(in_FirstShip),1),1,0) | F24: =IF(F$23>=DATE(YEAR(in_FirstShip),MONTH(in_FirstShip),1),1,0) | G24: =IF(G$23>=DATE(YEAR(in_FirstShip),MONTH(in_FirstShip),1),1,0) | H24: =IF(H$23>=DATE(YEAR(in_FirstShip),MONTH(in_FirstShip),1),1,0) | I24: =IF(I$23>=DATE(YEAR(in_FirstShip),MONTH(in_FirstShip),1),1,0) | J24: =IF(J$23>=DATE(YEAR(in_FirstShip),MONTH(in_FirstShip),1),1,0) | ... Q24: =IF(Q$23>=DATE(YEAR(in_FirstShip),MONTH(in_FirstShip),1),1,0)
A26: DTC customers and orders
A27: Waitlist first orders (first ship month only) | B27: Waitlist x conversion | C27: =IF(EOMONTH(in_FirstShip,0)=EOMONTH(C$23,0),in_WaitSize*in_WaitConv*$B$4,0) | D27: =IF(EOMONTH(in_FirstShip,0)=EOMONTH(D$23,0),in_WaitSize*in_WaitConv*$B$4,0) | E27: =IF(EOMONTH(in_FirstShip,0)=EOMONTH(E$23,0),in_WaitSize*in_WaitConv*$B$4,0) | F27: =IF(EOMONTH(in_FirstShip,0)=EOMONTH(F$23,0),in_WaitSize*in_WaitConv*$B$4,0) | G27: =IF(EOMONTH(in_FirstShip,0)=EOMONTH(G$23,0),in_WaitSize*in_WaitConv*$B$4,0) | H27: =IF(EOMONTH(in_FirstShip,0)=EOMONTH(H$23,0),in_WaitSize*in_WaitConv*$B$4,0) | I27: =IF(EOMONTH(in_FirstShip,0)=EOMONTH(I$23,0),in_WaitSize*in_WaitConv*$B$4,0) | J27: =IF(EOMONTH(in_FirstShip,0)=EOMONTH(J$23,0),in_WaitSize*in_WaitConv*$B$4,0) | ... Q27: =IF(EOMONTH(in_FirstShip,0)=EOMONTH(Q$23,0),in_WaitSize*in_WaitConv*$B$4,0) | R27: =SUM(C27:Q27)
A28: Organic new customers | C28: =IFERROR(INDEX(Inputs!$B$98:$B$107,MATCH(C$23,Inputs!$A$98:$A$107,0)),0)*$B$4*C24 | D28: =IFERROR(INDEX(Inputs!$B$98:$B$107,MATCH(D$23,Inputs!$A$98:$A$107,0)),0)*$B$4*D24 | E28: =IFERROR(INDEX(Inputs!$B$98:$B$107,MATCH(E$23,Inputs!$A$98:$A$107,0)),0)*$B$4*E24 | F28: =IFERROR(INDEX(Inputs!$B$98:$B$107,MATCH(F$23,Inputs!$A$98:$A$107,0)),0)*$B$4*F24 | G28: =IFERROR(INDEX(Inputs!$B$98:$B$107,MATCH(G$23,Inputs!$A$98:$A$107,0)),0)*$B$4*G24 | H28: =IFERROR(INDEX(Inputs!$B$98:$B$107,MATCH(H$23,Inputs!$A$98:$A$107,0)),0)*$B$4*H24 | I28: =IFERROR(INDEX(Inputs!$B$98:$B$107,MATCH(I$23,Inputs!$A$98:$A$107,0)),0)*$B$4*I24 | J28: =IFERROR(INDEX(Inputs!$B$98:$B$107,MATCH(J$23,Inputs!$A$98:$A$107,0)),0)*$B$4*J24 | ... Q28: =IFERROR(INDEX(Inputs!$B$98:$B$107,MATCH(Q$23,Inputs!$A$98:$A$107,0)),0)*$B$4*Q24 | R28: =SUM(C28:Q28)
A29: Paid new customers | C29: =IFERROR(INDEX(Inputs!$C$98:$C$107,MATCH(C$23,Inputs!$A$98:$A$107,0)),0)*$B$4*C24 | D29: =IFERROR(INDEX(Inputs!$C$98:$C$107,MATCH(D$23,Inputs!$A$98:$A$107,0)),0)*$B$4*D24 | E29: =IFERROR(INDEX(Inputs!$C$98:$C$107,MATCH(E$23,Inputs!$A$98:$A$107,0)),0)*$B$4*E24 | F29: =IFERROR(INDEX(Inputs!$C$98:$C$107,MATCH(F$23,Inputs!$A$98:$A$107,0)),0)*$B$4*F24 | G29: =IFERROR(INDEX(Inputs!$C$98:$C$107,MATCH(G$23,Inputs!$A$98:$A$107,0)),0)*$B$4*G24 | H29: =IFERROR(INDEX(Inputs!$C$98:$C$107,MATCH(H$23,Inputs!$A$98:$A$107,0)),0)*$B$4*H24 | I29: =IFERROR(INDEX(Inputs!$C$98:$C$107,MATCH(I$23,Inputs!$A$98:$A$107,0)),0)*$B$4*I24 | J29: =IFERROR(INDEX(Inputs!$C$98:$C$107,MATCH(J$23,Inputs!$A$98:$A$107,0)),0)*$B$4*J24 | ... Q29: =IFERROR(INDEX(Inputs!$C$98:$C$107,MATCH(Q$23,Inputs!$A$98:$A$107,0)),0)*$B$4*Q24 | R29: =SUM(C29:Q29)
A30: Total new DTC customers | C30: =C27+C28+C29 | D30: =D27+D28+D29 | E30: =E27+E28+E29 | F30: =F27+F28+F29 | G30: =G27+G28+G29 | H30: =H27+H28+H29 | I30: =I27+I28+I29 | J30: =J27+J28+J29 | ... Q30: =Q27+Q28+Q29 | R30: =SUM(C30:Q30)
A31: New subscribers | C31: =C30*in_SubShare | D31: =D30*in_SubShare | E31: =E30*in_SubShare | F31: =F30*in_SubShare | G31: =G30*in_SubShare | H31: =H30*in_SubShare | I31: =I30*in_SubShare | J31: =J30*in_SubShare | ... Q31: =Q30*in_SubShare | R31: =SUM(C31:Q31)
A32: Active subscribers, end of month (= subscription orders) | B32: 1 pouch/month each | C32: =C31 | D32: =C32*(1-in_SubChurn)+D31 | E32: =D32*(1-in_SubChurn)+E31 | F32: =E32*(1-in_SubChurn)+F31 | G32: =F32*(1-in_SubChurn)+G31 | H32: =G32*(1-in_SubChurn)+H31 | I32: =H32*(1-in_SubChurn)+I31 | J32: =I32*(1-in_SubChurn)+J31 | K32: =J32*(1-in_SubChurn)+K31 | ... Q32: =P32*(1-in_SubChurn)+Q31
A33: One-off first orders | C33: =C30*(1-in_SubShare) | D33: =D30*(1-in_SubShare) | E33: =E30*(1-in_SubShare) | F33: =F30*(1-in_SubShare) | G33: =G30*(1-in_SubShare) | H33: =H30*(1-in_SubShare) | I33: =I30*(1-in_SubShare) | J33: =J30*(1-in_SubShare) | ... Q33: =Q30*(1-in_SubShare) | R33: =SUM(C33:Q33)
A34: One-off repeat orders | C34: =0 | D34: =C35*in_Repeat | E34: =D35*in_Repeat | F34: =E35*in_Repeat | G34: =F35*in_Repeat | H34: =G35*in_Repeat | I34: =H35*in_Repeat | J34: =I35*in_Repeat | K34: =J35*in_Repeat | ... Q34: =P35*in_Repeat | R34: =SUM(C34:Q34)
A35: Total one-off pouch orders | C35: =C33+C34 | D35: =D33+D34 | E35: =E33+E34 | F35: =F33+F34 | G35: =G33+G34 | H35: =H33+H34 | I35: =I33+I34 | J35: =J33+J34 | ... Q35: =Q33+Q34 | R35: =SUM(C35:Q35)
A36: Total DTC pouch orders (one-off + subscription) | C36: =C35+C32 | D36: =D35+D32 | E36: =E35+E32 | F36: =F35+F32 | G36: =G35+G32 | H36: =H35+H32 | I36: =I35+I32 | J36: =J35+J32 | ... Q36: =Q35+Q32 | R36: =SUM(C36:Q36)
A37: DTC stick-box orders | C37: =C36*in_StickAttach | D37: =D36*in_StickAttach | E37: =E36*in_StickAttach | F37: =F36*in_StickAttach | G37: =G36*in_StickAttach | H37: =H36*in_StickAttach | I37: =I36*in_StickAttach | J37: =J36*in_StickAttach | ... Q37: =Q36*in_StickAttach | R37: =SUM(C37:Q37)
A39: Wholesale (direct to stores)
A40: New store accounts | C40: =IFERROR(INDEX(Inputs!$D$98:$D$107,MATCH(C$23,Inputs!$A$98:$A$107,0)),0)*$B$4*C24 | D40: =IFERROR(INDEX(Inputs!$D$98:$D$107,MATCH(D$23,Inputs!$A$98:$A$107,0)),0)*$B$4*D24 | E40: =IFERROR(INDEX(Inputs!$D$98:$D$107,MATCH(E$23,Inputs!$A$98:$A$107,0)),0)*$B$4*E24 | F40: =IFERROR(INDEX(Inputs!$D$98:$D$107,MATCH(F$23,Inputs!$A$98:$A$107,0)),0)*$B$4*F24 | G40: =IFERROR(INDEX(Inputs!$D$98:$D$107,MATCH(G$23,Inputs!$A$98:$A$107,0)),0)*$B$4*G24 | H40: =IFERROR(INDEX(Inputs!$D$98:$D$107,MATCH(H$23,Inputs!$A$98:$A$107,0)),0)*$B$4*H24 | I40: =IFERROR(INDEX(Inputs!$D$98:$D$107,MATCH(I$23,Inputs!$A$98:$A$107,0)),0)*$B$4*I24 | J40: =IFERROR(INDEX(Inputs!$D$98:$D$107,MATCH(J$23,Inputs!$A$98:$A$107,0)),0)*$B$4*J24 | ... Q40: =IFERROR(INDEX(Inputs!$D$98:$D$107,MATCH(Q$23,Inputs!$A$98:$A$107,0)),0)*$B$4*Q24 | R40: =SUM(C40:Q40)
A41: Active store accounts, end of month | C41: =C40 | D41: =C41*(1-in_StoreChurn)+D40 | E41: =D41*(1-in_StoreChurn)+E40 | F41: =E41*(1-in_StoreChurn)+F40 | G41: =F41*(1-in_StoreChurn)+G40 | H41: =G41*(1-in_StoreChurn)+H40 | I41: =H41*(1-in_StoreChurn)+I40 | J41: =I41*(1-in_StoreChurn)+J40 | K41: =J41*(1-in_StoreChurn)+K40 | ... Q41: =P41*(1-in_StoreChurn)+Q40
A42: Wholesale pouches shipped | C42: =C41*in_PouchPerStore | D42: =D41*in_PouchPerStore | E42: =E41*in_PouchPerStore | F42: =F41*in_PouchPerStore | G42: =G41*in_PouchPerStore | H42: =H41*in_PouchPerStore | I42: =I41*in_PouchPerStore | J42: =J41*in_PouchPerStore | ... Q42: =Q41*in_PouchPerStore | R42: =SUM(C42:Q42)
A43: Wholesale sticks shipped | C43: =C41*in_StickPerStore | D43: =D41*in_StickPerStore | E43: =E41*in_StickPerStore | F43: =F41*in_StickPerStore | G43: =G41*in_StickPerStore | H43: =H41*in_StickPerStore | I43: =I41*in_StickPerStore | J43: =J41*in_StickPerStore | ... Q43: =Q41*in_StickPerStore | R43: =SUM(C43:Q43)
A45: Pouch inventory (units)
...

Sheet calc_Standard_Low
A1: Calculation copy: Standard runs, Low demand (feeds Scenarios; do not edit)
A2: Months Oct 2026 to Dec 2027. All figures are projections from the Inputs sheet, not actual results. Cash view: inventory is a cash outflow when bought; COGS appears only in the operating view at the bottom.
A3: Run-size mode | B3: ="Standard"
A4: Demand multiplier | B4: =in_MultLow
A5: Demand case | B5: ="Low"
A6: Pouch cost of goods (by mode) | B6: =IF($B$3="Lean",in_CogsLean,in_CogsStd)
A7: Stick cost of goods (by mode) | B7: =IF($B$3="Lean",in_StickCogsLean,in_StickCogsStd)
A8: Pouch run size (by mode) | B8: =IF($B$3="Lean",in_RunLean,in_RunStd)
A9: Stick run size (by mode) | B9: =IF($B$3="Lean",in_StickRunLean,in_StickRunStd)
A10: Sample credit on first order (by mode) | B10: =IF($B$3="Lean",in_SampleCreditLean,in_SampleCreditStd)
A12: Summary for this sheet's mode and case
A13: Lowest cash balance | B13: =MIN($C$120:$Q$120)
A14: Month of lowest cash balance | B14: =INDEX($C$23:$Q$23,MATCH(MIN($C$120:$Q$120),$C$120:$Q$120,0))
A15: Peak funding need (lowest cumulative net cash flow) | B15: =MIN(0,MIN($C$119:$Q$119))
A16: Operating break-even month (first month operating profit >= 0) | B16: =IFERROR(INDEX($C$23:$Q$23,MATCH(1,$C$127:$Q$127,0)),"Not by Dec 2027")
A17: Cash payback month (cumulative net cash flow back to >= 0) | B17: =IFERROR(INDEX($C$23:$Q$23,MATCH(1,$C$128:$Q$128,0)),"Not by Dec 2027")
A18: Cash balance, end of Jun 2027 | B18: =IFERROR(INDEX($C$120:$Q$120,MATCH(DATE(2027,6,1),$C$23:$Q$23,0)),"n/a")
A19: Cash balance, end of Dec 2027 | B19: =IFERROR(INDEX($C$120:$Q$120,MATCH(DATE(2027,12,1),$C$23:$Q$23,0)),"n/a")
A20: Stockout check (pouch + stick units short; should be 0) | B20: =SUM($C$54:$Q$54)+SUM($C$65:$Q$65)
A21: Operating profit, Oct 2026 to Dec 2027 (launch costs excluded) | B21: =SUM($C$126:$Q$126)
A23: Line | B23: Note | C23: =DATE(YEAR(in_ModelStart),MONTH(in_ModelStart),1) | D23: =EDATE(C23,1) | E23: =EDATE(D23,1) | F23: =EDATE(E23,1) | G23: =EDATE(F23,1) | H23: =EDATE(G23,1) | I23: =EDATE(H23,1) | J23: =EDATE(I23,1) | K23: =EDATE(J23,1) | ... Q23: =EDATE(P23,1) | R23: Total
A24: Selling? (1 from the first ship month) | C24: =IF(C$23>=DATE(YEAR(in_FirstShip),MONTH(in_FirstShip),1),1,0) | D24: =IF(D$23>=DATE(YEAR(in_FirstShip),MONTH(in_FirstShip),1),1,0) | E24: =IF(E$23>=DATE(YEAR(in_FirstShip),MONTH(in_FirstShip),1),1,0) | F24: =IF(F$23>=DATE(YEAR(in_FirstShip),MONTH(in_FirstShip),1),1,0) | G24: =IF(G$23>=DATE(YEAR(in_FirstShip),MONTH(in_FirstShip),1),1,0) | H24: =IF(H$23>=DATE(YEAR(in_FirstShip),MONTH(in_FirstShip),1),1,0) | I24: =IF(I$23>=DATE(YEAR(in_FirstShip),MONTH(in_FirstShip),1),1,0) | J24: =IF(J$23>=DATE(YEAR(in_FirstShip),MONTH(in_FirstShip),1),1,0) | ... Q24: =IF(Q$23>=DATE(YEAR(in_FirstShip),MONTH(in_FirstShip),1),1,0)
A26: DTC customers and orders
A27: Waitlist first orders (first ship month only) | B27: Waitlist x conversion | C27: =IF(EOMONTH(in_FirstShip,0)=EOMONTH(C$23,0),in_WaitSize*in_WaitConv*$B$4,0) | D27: =IF(EOMONTH(in_FirstShip,0)=EOMONTH(D$23,0),in_WaitSize*in_WaitConv*$B$4,0) | E27: =IF(EOMONTH(in_FirstShip,0)=EOMONTH(E$23,0),in_WaitSize*in_WaitConv*$B$4,0) | F27: =IF(EOMONTH(in_FirstShip,0)=EOMONTH(F$23,0),in_WaitSize*in_WaitConv*$B$4,0) | G27: =IF(EOMONTH(in_FirstShip,0)=EOMONTH(G$23,0),in_WaitSize*in_WaitConv*$B$4,0) | H27: =IF(EOMONTH(in_FirstShip,0)=EOMONTH(H$23,0),in_WaitSize*in_WaitConv*$B$4,0) | I27: =IF(EOMONTH(in_FirstShip,0)=EOMONTH(I$23,0),in_WaitSize*in_WaitConv*$B$4,0) | J27: =IF(EOMONTH(in_FirstShip,0)=EOMONTH(J$23,0),in_WaitSize*in_WaitConv*$B$4,0) | ... Q27: =IF(EOMONTH(in_FirstShip,0)=EOMONTH(Q$23,0),in_WaitSize*in_WaitConv*$B$4,0) | R27: =SUM(C27:Q27)
